Workbook

Sheet Raw Data
A1: Invoice No | B1: Vendor Name | C1: Department | D1: Invoice Date | E1: Due Date | F1: Amount (₹) | G1: Payment Status | H1: Month | I1: PO Number | J1: Remarks
A2: INV-1001 | B2: Tata Consultancy | C2: Finance | D2: 21/01/2026 | E2: 04/02/2026 | F2: 16556 | G2: Paid | H2: Jan-26 | I2: PO-2000 | J2: On time
A3: INV-1002 | B3: Infosys Ltd | C3: IT | D3: 24/01/2026 | E3: 09/02/2026 | F3: 74196 | G3: Paid | H3: Jan-26 | I3: PO-2001 | J3: On time
A4: INV-1003 | B4: Wipro India | C4: HR | D4: 08/02/2026 | E4: 05/03/2026 | F4: 36868 | G4: Paid | H4: Feb-26 | I4: PO-2002 | J4: On time
A5: INV-1004 | B5: HCL Tech | C5: Operations | D5: 22/02/2026 | E5: 24/03/2026 | F5: 152964 | G5: Pending | H5: Feb-26 | I5: PO-2003
A6: INV-1005 | B6: Reliance Retail | C6: Procurement | D6: 03/03/2026 | E6: 19/04/2026 | F6: 120604 | G6: Overdue | H6: Mar-26 | I6: PO-2004 | J6: Follow up needed
A7: INV-1006 | B7: Sun Pharma | C7: Finance | D7: 02/03/2026 | E7: 01/04/2026 | F7: 34561 | G7: Paid | H7: Mar-26 | I7: PO-2005 | J7: On time
A8: INV-1007 | B8: Asian Paints | C8: IT | D8: 07/04/2026 | E8: 08/05/2026 | F8: 142475 | G8: Paid | H8: Apr-26 | I8: PO-2006 | J8: On time
A9: INV-1008 | B9: HDFC Securities | C9: HR | D9: 20/04/2026 | E9: 01/05/2026 | F9: 157127 | G9: Paid | H9: Apr-26 | I9: PO-2007 | J9: On time
A10: INV-1009 | B10: Bajaj Auto | C10: Operations | D10: 07/05/2026 | E10: 23/06/2026 | F10: 180363 | G10: Pending | H10: May-26 | I10: PO-2008
A11: INV-1010 | B11: Mahindra Ltd | C11: Procurement | D11: 23/05/2026 | E11: 18/06/2026 | F11: 119974 | G11: Overdue | H11: May-26 | I11: PO-2009 | J11: Follow up needed
A12: INV-1011 | B12: Tata Consultancy | C12: Finance | D12: 08/06/2026 | E12: 15/07/2026 | F12: 164472 | G12: Paid | H12: Jun-26 | I12: PO-2010 | J12: On time
A13: INV-1012 | B13: Infosys Ltd | C13: IT | D13: 09/06/2026 | E13: 26/07/2026 | F13: 11703 | G13: Paid | H13: Jun-26 | I13: PO-2011 | J13: On time
A14: INV-1013 | B14: Wipro India | C14: HR | D14: 25/01/2026 | E14: 26/02/2026 | F14: 51853 | G14: Paid | H14: Jan-26 | I14: PO-2012 | J14: On time
A15: INV-1014 | B15: HCL Tech | C15: Operations | D15: 23/01/2026 | E15: 14/02/2026 | F15: 99194 | G15: Pending | H15: Jan-26 | I15: PO-2013
A16: INV-1015 | B16: Reliance Retail | C16: Procurement | D16: 09/02/2026 | E16: 05/03/2026 | F16: 66443 | G16: Overdue | H16: Feb-26 | I16: PO-2014 | J16: Follow up needed
A17: INV-1016 | B17: Sun Pharma | C17: Finance | D17: 25/02/2026 | E17: 11/03/2026 | F17: 36793 | G17: Paid | H17: Feb-26 | I17: PO-2015 | J17: On time
A18: INV-1017 | B18: Asian Paints | C18: IT | D18: 03/03/2026 | E18: 13/04/2026 | F18: 35353 | G18: Paid | H18: Mar-26 | I18: PO-2016 | J18: On time
A19: INV-1018 | B19: HDFC Securities | C19: HR | D19: 12/03/2026 | E19: 28/04/2026 | F19: 100165 | G19: Paid | H19: Mar-26 | I19: PO-2017 | J19: On time
A20: INV-1019 | B20: Bajaj Auto | C20: Operations | D20: 20/04/2026 | E20: 09/05/2026 | F20: 21390 | G20: Pending | H20: Apr-26 | I20: PO-2018
A21: INV-1020 | B21: Mahindra Ltd | C21: Procurement | D21: 24/04/2026 | E21: 15/05/2026 | F21: 150568 | G21: Overdue | H21: Apr-26 | I21: PO-2019 | J21: Follow up needed
A22: INV-1021 | B22: Tata Consultancy | C22: Finance | D22: 04/05/2026 | E22: 13/06/2026 | F22: 30656 | G22: Paid | H22: May-26 | I22: PO-2020 | J22: On time
A23: INV-1022 | B23: Infosys Ltd | C23: IT | D23: 18/05/2026 | E23: 10/06/2026 | F23: 174794 | G23: Paid | H23: May-26 | I23: PO-2021 | J23: On time
A24: INV-1023 | B24: Wipro India | C24: HR | D24: 20/06/2026 | E24: 28/07/2026 | F24: 104800 | G24: Paid | H24: Jun-26 | I24: PO-2022 | J24: On time
A25: INV-1024 | B25: HCL Tech | C25: Operations | D25: 19/06/2026 | E25: 07/07/2026 | F25: 194699 | G25: Pending | H25: Jun-26 | I25: PO-2023
A26: INV-1025 | B26: Reliance Retail | C26: Procurement | D26: 03/01/2026 | E26: 02/02/2026 | F26: 183346 | G26: Overdue | H26: Jan-26 | I26: PO-2024 | J26: Follow up needed
A27: INV-1026 | B27: Sun Pharma | C27: Finance | D27: 08/01/2026 | E27: 25/02/2026 | F27: 85861 | G27: Paid | H27: Jan-26 | I27: PO-2025 | J27: On time
A28: INV-1027 | B28: Asian Paints | C28: IT | D28: 03/02/2026 | E28: 28/03/2026 | F28: 71024 | G28: Paid | H28: Feb-26 | I28: PO-2026 | J28: On time
A29: INV-1028 | B29: HDFC Securities | C29: HR | D29: 28/02/2026 | E29: 04/03/2026 | F29: 109647 | G29: Paid | H29: Feb-26 | I29: PO-2027 | J29: On time
A30: INV-1029 | B30: Bajaj Auto | C30: Operations | D30: 09/03/2026 | E30: 15/04/2026 | F30: 176640 | G30: Pending | H30: Mar-26 | I30: PO-2028
A31: INV-1030 | B31: Mahindra Ltd | C31: Procurement | D31: 27/03/2026 | E31: 12/04/2026 | F31: 52638 | G31: Overdue | H31: Mar-26 | I31: PO-2029 | J31: Follow up needed
A32: INV-1031 | B32: Tata Consultancy | C32: Finance | D32: 12/04/2026 | E32: 12/05/2026 | F32: 64921 | G32: Paid | H32: Apr-26 | I32: PO-2030 | J32: On time
A33: INV-1032 | B33: Infosys Ltd | C33: IT | D33: 22/04/2026 | E33: 09/05/2026 | F33: 193977 | G33: Paid | H33: Apr-26 | I33: PO-2031 | J33: On time
A34: INV-1033 | B34: Wipro India | C34: HR | D34: 22/05/2026 | E34: 21/06/2026 | F34: 28717 | G34: Paid | H34: May-26 | I34: PO-2032 | J34: On time
A35: INV-1034 | B35: HCL Tech | C35: Operations | D35: 20/05/2026 | E35: 21/06/2026 | F35: 54862 | G35: Pending | H35: May-26 | I35: PO-2033
A36: INV-1035 | B36: Reliance Retail | C36: Procurement | D36: 18/06/2026 | E36: 24/07/2026 | F36: 74175 | G36: Overdue | H36: Jun-26 | I36: PO-2034 | J36: Follow up needed
A37: INV-1036 | B37: Sun Pharma | C37: Finance | D37: 06/06/2026 | E37: 15/07/2026 | F37: 109471 | G37: Paid | H37: Jun-26 | I37: PO-2035 | J37: On time
A38: INV-1037 | B38: Asian Paints | C38: IT | D38: 09/01/2026 | E38: 21/02/2026 | F38: 190397 | G38: Paid | H38: Jan-26 | I38: PO-2036 | J38: On time
A39: INV-1038 | B39: HDFC Securities | C39: HR | D39: 18/01/2026 | E39: 08/02/2026 | F39: 189467 | G39: Paid | H39: Jan-26 | I39: PO-2037 | J39: On time
A40: INV-1039 | B40: Bajaj Auto | C40: Operations | D40: 11/02/2026 | E40: 27/03/2026 | F40: 24663 | G40: Pending | H40: Feb-26 | I40: PO-2038
...

Sheet MIS Summary
A1: 📊 ACCOUNTS PAYABLE — MIS REPORT | JUNE 2026
A2: Prepared by: Zainab Kousar Shaikh | IBM India Pvt Ltd | Accounts Payable
A4: Total Invoices | C4: Total Amount (₹) | E4: Paid Amount (₹) | G4: Pending Amount (₹) | I4: Overdue Amount (₹)
A5: =COUNTA('Raw Data'!A2:A61) -> 60 | C5: =SUM('Raw Data'!F2:F61) -> 6079620 | E5: =SUMIF('Raw Data'!G2:G61,"Paid",'Raw Data'!F2:F61) -> 3456384 | G5: =SUMIF('Raw Data'!G2:G61,"Pending",'Raw Data'!F2:F61) -> 1469717 | I5: =SUMIF('Raw Data'!G2:G61,"Overdue",'Raw Data'!F2:F61) -> 1153519
A10: PAYMENT STATUS BREAKDOWN | F10: TOP VENDOR WISE AMOUNT
A11: Status | B11: Invoice Count | C11: Total Amount (₹) | D11: % of Total | F11: Vendor | G11: Total Amount (₹) | H11: Paid (₹) | I11: Status
A12: Paid | B12: =COUNTIF('Raw Data'!G2:G61,"Paid") -> 36 | C12: =SUMIF('Raw Data'!G2:G61,"Paid",'Raw Data'!F2:F61) -> 3456384 | D12: =C12/C$15 -> 0.56851974 | F12: Tata Consultancy | G12: =SUMIF('Raw Data'!B2:B61,"Tata Consultancy",'Raw Data'!F2:F61) -> 425598 | H12: =SUMIFS('Raw Data'!F2:F61,'Raw Data'!B2:B61,"Tata Consultancy",'Raw Data'!G2:G61,"Paid") -> 425598 | I12: Active
A13: Pending | B13: =COUNTIF('Raw Data'!G2:G61,"Pending") -> 12 | C13: =SUMIF('Raw Data'!G2:G61,"Pending",'Raw Data'!F2:F61) -> 1469717 | D13: =C13/C$15 -> 0.24174488 | F13: Infosys Ltd | G13: =SUMIF('Raw Data'!B2:B61,"Infosys Ltd",'Raw Data'!F2:F61) -> 558720 | H13: =SUMIFS('Raw Data'!F2:F61,'Raw Data'!B2:B61,"Infosys Ltd",'Raw Data'!G2:G61,"Paid") -> 558720 | I13: Active
A14: Overdue | B14: =COUNTIF('Raw Data'!G2:G61,"Overdue") -> 12 | C14: =SUMIF('Raw Data'!G2:G61,"Overdue",'Raw Data'!F2:F61) -> 1153519 | D14: =C14/C$15 -> 0.18973538 | F14: Wipro India | G14: =SUMIF('Raw Data'!B2:B61,"Wipro India",'Raw Data'!F2:F61) -> 366666 | H14: =SUMIFS('Raw Data'!F2:F61,'Raw Data'!B2:B61,"Wipro India",'Raw Data'!G2:G61,"Paid") -> 366666 | I14: Active
A15: TOTAL | B15: =SUM(B12:B14) -> 60 | C15: =SUM(C12:C14) -> 6079620 | D15: =SUM(D12:D14) -> 1 | F15: HCL Tech | G15: =SUMIF('Raw Data'!B2:B61,"HCL Tech",'Raw Data'!F2:F61) -> 763255 | H15: =SUMIFS('Raw Data'!F2:F61,'Raw Data'!B2:B61,"HCL Tech",'Raw Data'!G2:G61,"Paid") -> 0 | I15: Active
F16: Reliance Retail | G16: =SUMIF('Raw Data'!B2:B61,"Reliance Retail",'Raw Data'!F2:F61) -> 685717 | H16: =SUMIFS('Raw Data'!F2:F61,'Raw Data'!B2:B61,"Reliance Retail",'Raw Data'!G2:G61,"Paid") -> 0 | I16: Active
F17: Sun Pharma | G17: =SUMIF('Raw Data'!B2:B61,"Sun Pharma",'Raw Data'!F2:F61) -> 445985 | H17: =SUMIFS('Raw Data'!F2:F61,'Raw Data'!B2:B61,"Sun Pharma",'Raw Data'!G2:G61,"Paid") -> 445985 | I17: Active
F18: Asian Paints | G18: =SUMIF('Raw Data'!B2:B61,"Asian Paints",'Raw Data'!F2:F61) -> 751432 | H18: =SUMIFS('Raw Data'!F2:F61,'Raw Data'!B2:B61,"Asian Paints",'Raw Data'!G2:G61,"Paid") -> 751432 | I18: Active
F19: HDFC Securities | G19: =SUMIF('Raw Data'!B2:B61,"HDFC Securities",'Raw Data'!F2:F61) -> 907983 | H19: =SUMIFS('Raw Data'!F2:F61,'Raw Data'!B2:B61,"HDFC Securities",'Raw Data'!G2:G61,"Paid") -> 907983 | I19: Active

Sheet Monthly Trend
A1: MONTH-WISE PAYMENT TREND — JAN to JUN 2026
A2: Month | B2: Total Invoices | C2: Total Amount (₹) | D2: Paid (₹) | E2: Pending (₹) | F2: Overdue (₹) | G2: Collection %
A3: Jan-26 | B3: =COUNTIF('Raw Data'!H2:H61,"Jan-26") -> 10 | C3: =SUMIF('Raw Data'!H2:H61,"Jan-26",'Raw Data'!F2:F61) -> 1051832 | D3: =SUMIFS('Raw Data'!F2:F61,'Raw Data'!H2:H61,"Jan-26",'Raw Data'!G2:G61,"Paid") -> 608330 | E3: =SUMIFS('Raw Data'!F2:F61,'Raw Data'!H2:H61,"Jan-26",'Raw Data'!G2:G61,"Pending") -> 213894 | F3: =SUMIFS('Raw Data'!F2:F61,'Raw Data'!H2:H61,"Jan-26",'Raw Data'!G2:G61,"Overdue") -> 229608 | G3: =IF(C3=0,0,D3/C3) -> 0.57835282
A4: Feb-26 | B4: =COUNTIF('Raw Data'!H2:H61,"Feb-26") -> 10 | C4: =SUMIF('Raw Data'!H2:H61,"Feb-26",'Raw Data'!F2:F61) -> 589390 | D4: =SUMIFS('Raw Data'!F2:F61,'Raw Data'!H2:H61,"Feb-26",'Raw Data'!G2:G61,"Paid") -> 326906 | E4: =SUMIFS('Raw Data'!F2:F61,'Raw Data'!H2:H61,"Feb-26",'Raw Data'!G2:G61,"Pending") -> 177627 | F4: =SUMIFS('Raw Data'!F2:F61,'Raw Data'!H2:H61,"Feb-26",'Raw Data'!G2:G61,"Overdue") -> 84857 | G4: =IF(C4=0,0,D4/C4) -> 0.55465142
A5: Mar-26 | B5: =COUNTIF('Raw Data'!H2:H61,"Mar-26") -> 10 | C5: =SUMIF('Raw Data'!H2:H61,"Mar-26",'Raw Data'!F2:F61) -> 873034 | D5: =SUMIFS('Raw Data'!F2:F61,'Raw Data'!H2:H61,"Mar-26",'Raw Data'!G2:G61,"Paid") -> 402486 | E5: =SUMIFS('Raw Data'!F2:F61,'Raw Data'!H2:H61,"Mar-26",'Raw Data'!G2:G61,"Pending") -> 297306 | F5: =SUMIFS('Raw Data'!F2:F61,'Raw Data'!H2:H61,"Mar-26",'Raw Data'!G2:G61,"Overdue") -> 173242 | G5: =IF(C5=0,0,D5/C5) -> 0.46101985
A6: Apr-26 | B6: =COUNTIF('Raw Data'!H2:H61,"Apr-26") -> 10 | C6: =SUMIF('Raw Data'!H2:H61,"Apr-26",'Raw Data'!F2:F61) -> 1207378 | D6: =SUMIFS('Raw Data'!F2:F61,'Raw Data'!H2:H61,"Apr-26",'Raw Data'!G2:G61,"Paid") -> 783686 | E6: =SUMIFS('Raw Data'!F2:F61,'Raw Data'!H2:H61,"Apr-26",'Raw Data'!G2:G61,"Pending") -> 162260 | F6: =SUMIFS('Raw Data'!F2:F61,'Raw Data'!H2:H61,"Apr-26",'Raw Data'!G2:G61,"Overdue") -> 261432 | G6: =IF(C6=0,0,D6/C6) -> 0.6490809
A7: May-26 | B7: =COUNTIF('Raw Data'!H2:H61,"May-26") -> 10 | C7: =SUMIF('Raw Data'!H2:H61,"May-26",'Raw Data'!F2:F61) -> 1109610 | D7: =SUMIFS('Raw Data'!F2:F61,'Raw Data'!H2:H61,"May-26",'Raw Data'!G2:G61,"Paid") -> 624126 | E7: =SUMIFS('Raw Data'!F2:F61,'Raw Data'!H2:H61,"May-26",'Raw Data'!G2:G61,"Pending") -> 235225 | F7: =SUMIFS('Raw Data'!F2:F61,'Raw Data'!H2:H61,"May-26",'Raw Data'!G2:G61,"Overdue") -> 250259 | G7: =IF(C7=0,0,D7/C7) -> 0.5624733
A8: Jun-26 | B8: =COUNTIF('Raw Data'!H2:H61,"Jun-26") -> 10 | C8: =SUMIF('Raw Data'!H2:H61,"Jun-26",'Raw Data'!F2:F61) -> 1248376 | D8: =SUMIFS('Raw Data'!F2:F61,'Raw Data'!H2:H61,"Jun-26",'Raw Data'!G2:G61,"Paid") -> 710850 | E8: =SUMIFS('Raw Data'!F2:F61,'Raw Data'!H2:H61,"Jun-26",'Raw Data'!G2:G61,"Pending") -> 383405 | F8: =SUMIFS('Raw Data'!F2:F61,'Raw Data'!H2:H61,"Jun-26",'Raw Data'!G2:G61,"Overdue") -> 154121 | G8: =IF(C8=0,0,D8/C8) -> 0.56941979
A9: TOTAL | B9: =SUM(B3:B8) -> 60 | C9: =SUM(C3:C8) -> 6079620 | D9: =SUM(D3:D8) -> 3456384 | E9: =SUM(E3:E8) -> 1469717 | F9: =SUM(F3:F8) -> 1153519 | G9: =IFERROR(D9/C9,0) -> 0.56851974

Sheet Aging Analysis
A1: INVOICE AGING ANALYSIS — OVERDUE & PENDING
A2: Aging Bucket | B2: Invoice Count | C2: Total Amount (₹) | D2: % of Outstanding | E2: Action Required | F2: Priority
A3: 0–30 Days | B3: 14 | C3: 520000 | D3: =C3/SUM($C$3:$C$6) -> 0.47058824 | E3: Normal — Monitor | F3: Low
A4: 31–60 Days | B4: 8 | C4: 310000 | D4: =C4/SUM($C$3:$C$6) -> 0.28054299 | E4: Follow Up Required | F4: Medium
A5: 61–90 Days | B5: 5 | C5: 180000 | D5: =C5/SUM($C$3:$C$6) -> 0.16289593 | E5: Escalate to Manager | F5: High
A6: 90+ Days | B6: 3 | C6: 95000 | D6: =C6/SUM($C$3:$C$6) -> 0.085972851 | E6: Immediate Action | F6: Critical
A7: TOTAL | B7: =SUM(B3:B6) -> 30 | C7: =SUM(C3:C6) -> 1105000 | D7: =SUM(D3:D6) -> 1

Sheet Vendor Analysis
A1: VENDOR-WISE ACCOUNTS PAYABLE ANALYSIS
A2: Vendor Name | B2: Total Invoices | C2: Total Amount (₹) | D2: Paid (₹) | E2: Pending (₹) | F2: Overdue (₹) | G2: Payment Rate
A3: Tata Consultancy | B3: =COUNTIF('Raw Data'!B2:B61,"Tata Consultancy") -> 6 | C3: =SUMIF('Raw Data'!B2:B61,"Tata Consultancy",'Raw Data'!F2:F61) -> 425598 | D3: =SUMIFS('Raw Data'!F2:F61,'Raw Data'!B2:B61,"Tata Consultancy",'Raw Data'!G2:G61,"Paid") -> 425598 | E3: =SUMIFS('Raw Data'!F2:F61,'Raw Data'!B2:B61,"Tata Consultancy",'Raw Data'!G2:G61,"Pending") -> 0 | F3: =SUMIFS('Raw Data'!F2:F61,'Raw Data'!B2:B61,"Tata Consultancy",'Raw Data'!G2:G61,"Overdue") -> 0 | G3: =IF(C3=0,0,D3/C3) -> 1
A4: Infosys Ltd | B4: =COUNTIF('Raw Data'!B2:B61,"Infosys Ltd") -> 6 | C4: =SUMIF('Raw Data'!B2:B61,"Infosys Ltd",'Raw Data'!F2:F61) -> 558720 | D4: =SUMIFS('Raw Data'!F2:F61,'Raw Data'!B2:B61,"Infosys Ltd",'Raw Data'!G2:G61,"Paid") -> 558720 | E4: =SUMIFS('Raw Data'!F2:F61,'Raw Data'!B2:B61,"Infosys Ltd",'Raw Data'!G2:G61,"Pending") -> 0 | F4: =SUMIFS('Raw Data'!F2:F61,'Raw Data'!B2:B61,"Infosys Ltd",'Raw Data'!G2:G61,"Overdue") -> 0 | G4: =IF(C4=0,0,D4/C4) -> 1
A5: Wipro India | B5: =COUNTIF('Raw Data'!B2:B61,"Wipro India") -> 6 | C5: =SUMIF('Raw Data'!B2:B61,"Wipro India",'Raw Data'!F2:F61) -> 366666 | D5: =SUMIFS('Raw Data'!F2:F61,'Raw Data'!B2:B61,"Wipro India",'Raw Data'!G2:G61,"Paid") -> 366666 | E5: =SUMIFS('Raw Data'!F2:F61,'Raw Data'!B2:B61,"Wipro India",'Raw Data'!G2:G61,"Pending") -> 0 | F5: =SUMIFS('Raw Data'!F2:F61,'Raw Data'!B2:B61,"Wipro India",'Raw Data'!G2:G61,"Overdue") -> 0 | G5: =IF(C5=0,0,D5/C5) -> 1
A6: HCL Tech | B6: =COUNTIF('Raw Data'!B2:B61,"HCL Tech") -> 6 | C6: =SUMIF('Raw Data'!B2:B61,"HCL Tech",'Raw Data'!F2:F61) -> 763255 | D6: =SUMIFS('Raw Data'!F2:F61,'Raw Data'!B2:B61,"HCL Tech",'Raw Data'!G2:G61,"Paid") -> 0 | E6: =SUMIFS('Raw Data'!F2:F61,'Raw Data'!B2:B61,"HCL Tech",'Raw Data'!G2:G61,"Pending") -> 763255 | F6: =SUMIFS('Raw Data'!F2:F61,'Raw Data'!B2:B61,"HCL Tech",'Raw Data'!G2:G61,"Overdue") -> 0 | G6: =IF(C6=0,0,D6/C6) -> 0
A7: Reliance Retail | B7: =COUNTIF('Raw Data'!B2:B61,"Reliance Retail") -> 6 | C7: =SUMIF('Raw Data'!B2:B61,"Reliance Retail",'Raw Data'!F2:F61) -> 685717 | D7: =SUMIFS('Raw Data'!F2:F61,'Raw Data'!B2:B61,"Reliance Retail",'Raw Data'!G2:G61,"Paid") -> 0 | E7: =SUMIFS('Raw Data'!F2:F61,'Raw Data'!B2:B61,"Reliance Retail",'Raw Data'!G2:G61,"Pending") -> 0 | F7: =SUMIFS('Raw Data'!F2:F61,'Raw Data'!B2:B61,"Reliance Retail",'Raw Data'!G2:G61,"Overdue") -> 685717 | G7: =IF(C7=0,0,D7/C7) -> 0
A8: Sun Pharma | B8: =COUNTIF('Raw Data'!B2:B61,"Sun Pharma") -> 6 | C8: =SUMIF('Raw Data'!B2:B61,"Sun Pharma",'Raw Data'!F2:F61) -> 445985 | D8: =SUMIFS('Raw Data'!F2:F61,'Raw Data'!B2:B61,"Sun Pharma",'Raw Data'!G2:G61,"Paid") -> 445985 | E8: =SUMIFS('Raw Data'!F2:F61,'Raw Data'!B2:B61,"Sun Pharma",'Raw Data'!G2:G61,"Pending") -> 0 | F8: =SUMIFS('Raw Data'!F2:F61,'Raw Data'!B2:B61,"Sun Pharma",'Raw Data'!G2:G61,"Overdue") -> 0 | G8: =IF(C8=0,0,D8/C8) -> 1
A9: Asian Paints | B9: =COUNTIF('Raw Data'!B2:B61,"Asian Paints") -> 6 | C9: =SUMIF('Raw Data'!B2:B61,"Asian Paints",'Raw Data'!F2:F61) -> 751432 | D9: =SUMIFS('Raw Data'!F2:F61,'Raw Data'!B2:B61,"Asian Paints",'Raw Data'!G2:G61,"Paid") -> 751432 | E9: =SUMIFS('Raw Data'!F2:F61,'Raw Data'!B2:B61,"Asian Paints",'Raw Data'!G2:G61,"Pending") -> 0 | F9: =SUMIFS('Raw Data'!F2:F61,'Raw Data'!B2:B61,"Asian Paints",'Raw Data'!G2:G61,"Overdue") -> 0 | G9: =IF(C9=0,0,D9/C9) -> 1
A10: HDFC Securities | B10: =COUNTIF('Raw Data'!B2:B61,"HDFC Securities") -> 6 | C10: =SUMIF('Raw Data'!B2:B61,"HDFC Securities",'Raw Data'!F2:F61) -> 907983 | D10: =SUMIFS('Raw Data'!F2:F61,'Raw Data'!B2:B61,"HDFC Securities",'Raw Data'!G2:G61,"Paid") -> 907983 | E10: =SUMIFS('Raw Data'!F2:F61,'Raw Data'!B2:B61,"HDFC Securities",'Raw Data'!G2:G61,"Pending") -> 0 | F10: =SUMIFS('Raw Data'!F2:F61,'Raw Data'!B2:B61,"HDFC Securities",'Raw Data'!G2:G61,"Overdue") -> 0 | G10: =IF(C10=0,0,D10/C10) -> 1
A11: Bajaj Auto | B11: =COUNTIF('Raw Data'!B2:B61,"Bajaj Auto") -> 6 | C11: =SUMIF('Raw Data'!B2:B61,"Bajaj Auto",'Raw Data'!F2:F61) -> 706462 | D11: =SUMIFS('Raw Data'!F2:F61,'Raw Data'!B2:B61,"Bajaj Auto",'Raw Data'!G2:G61,"Paid") -> 0 | E11: =SUMIFS('Raw Data'!F2:F61,'Raw Data'!B2:B61,"Bajaj Auto",'Raw Data'!G2:G61,"Pending") -> 706462 | F11: =SUMIFS('Raw Data'!F2:F61,'Raw Data'!B2:B61,"Bajaj Auto",'Raw Data'!G2:G61,"Overdue") -> 0 | G11: =IF(C11=0,0,D11/C11) -> 0
A12: Mahindra Ltd | B12: =COUNTIF('Raw Data'!B2:B61,"Mahindra Ltd") -> 6 | C12: =SUMIF('Raw Data'!B2:B61,"Mahindra Ltd",'Raw Data'!F2:F61) -> 467802 | D12: =SUMIFS('Raw Data'!F2:F61,'Raw Data'!B2:B61,"Mahindra Ltd",'Raw Data'!G2:G61,"Paid") -> 0 | E12: =SUMIFS('Raw Data'!F2:F61,'Raw Data'!B2:B61,"Mahindra Ltd",'Raw Data'!G2:G61,"Pending") -> 0 | F12: =SUMIFS('Raw Data'!F2:F61,'Raw Data'!B2:B61,"Mahindra Ltd",'Raw Data'!G2:G61,"Overdue") -> 467802 | G12: =IF(C12=0,0,D12/C12) -> 0
A13: GRAND TOTAL | B13: =SUM(B3:B12) -> 60 | C13: =SUM(C3:C12) -> 6079620 | D13: =SUM(D3:D12) -> 3456384 | E13: =SUM(E3:E12) -> 1469717 | F13: =SUM(F3:F12) -> 1153519 | G13: =IFERROR(D13/C13,0) -> 0.56851974

Sheet Exception Report
A1: ⚠️ EXCEPTION REPORT — ISSUES REQUIRING ATTENTION
A2: Invoice No | B2: Vendor | C2: Amount (₹) | D2: Issue Type | E2: Days Overdue | F2: Action
A3: INV-1015 | B3: Wipro India | C3: 85000 | D3: Overdue > 60 days | E3: 72 | F3: Escalate immediately
A4: INV-1028 | B4: HCL Tech | C4: 120000 | D4: Missing PO Number | E4: 0 | F4: Get PO from procurement
A5: INV-1033 | B5: Reliance Retail | C5: 45000 | D5: Duplicate Invoice | E5: 0 | F5: Hold — verify with vendor
A6: INV-1041 | B6: Sun Pharma | C6: 200000 | D6: Overdue > 90 days | E6: 95 | F6: Legal notice required
A7: INV-1052 | B7: Asian Paints | C7: 33000 | D7: Amount mismatch | E7: 0 | F7: Reconcile with PO
A8: INV-1058 | B8: Bajaj Auto | C8: 67000 | D8: Overdue > 30 days | E8: 38 | F8: Send payment reminder
